{"cells":[{"cell_type":"markdown","id":"dce782b3-f9c2-4734-8b51-9a384a162c9a","metadata":{},"source":["# **Tratamiento de errores**"]},{"cell_type":"markdown","id":"0ca97c19-9ebb-4dfa-9dda-07d630628390","metadata":{},"source":["## Qué es una Excepción (Exception)?\n"]},{"cell_type":"markdown","id":"5a54d9df-1fe6-40e0-8a21-d89c02efb388","metadata":{},"source":["Una excepción es un evento que ocurre durante la ejecución de un programa que interrumpe el flujo normal del mismo. Las excepciones suelen ser causadas por errores, como intentos de dividir por cero, acceso a una variable que no existe, o el manejo incorrecto de tipos de datos. Cuando una excepción ocurre, Python detiene la ejecución del código y busca una manera de manejar el error."]},{"cell_type":"markdown","id":"cc02ecf0-32b7-4af7-a3cd-12d6ca2d7365","metadata":{},"source":["### Ejemplos\n"]},{"cell_type":"code","execution_count":1,"id":"87f4e8f2-c879-43c5-8c12-1224978f03b4","metadata":{},"outputs":[{"ename":"ZeroDivisionError","evalue":"division by zero","output_type":"error","traceback":["\u001b[1;31m---------------------------------------------------------------------------\u001b[0m","\u001b[1;31mZeroDivisionError\u001b[0m                         Traceback (most recent call last)","Cell \u001b[1;32mIn[1], line 1\u001b[0m\n\u001b[1;32m----> 1\u001b[0m \u001b[38;5;241;43m1\u001b[39;49m\u001b[38;5;241;43m/\u001b[39;49m\u001b[38;5;241;43m0\u001b[39;49m\n","\u001b[1;31mZeroDivisionError\u001b[0m: division by zero"]}],"source":["1/0"]},{"cell_type":"markdown","id":"7eb1681b-346f-4396-8438-8bf9bf49750c","metadata":{},"source":["<code>ZeroDivisionError</code> ocurre cuando tratas de dividir por cero.\n"]},{"cell_type":"code","execution_count":2,"id":"f4887415-8a19-498e-9df2-3e2c48157209","metadata":{},"outputs":[{"ename":"NameError","evalue":"name 'a' is not defined","output_type":"error","traceback":["\u001b[1;31m---------------------------------------------------------------------------\u001b[0m","\u001b[1;31mNameError\u001b[0m                                 Traceback (most recent call last)","Cell \u001b[1;32mIn[2], line 1\u001b[0m\n\u001b[1;32m----> 1\u001b[0m y \u001b[38;5;241m=\u001b[39m \u001b[43ma\u001b[49m \u001b[38;5;241m+\u001b[39m \u001b[38;5;241m5\u001b[39m\n","\u001b[1;31mNameError\u001b[0m: name 'a' is not defined"]}],"source":["y = a + 5"]},{"cell_type":"markdown","id":"5216dcd8-4dcd-42b8-9a03-3ab4c2f58a60","metadata":{},"source":["<code>NameError</code> -- en este caso, significa que estas tratando de usar una variable que no ha sido definida.\n"]},{"cell_type":"code","execution_count":3,"id":"12cc6066-3fd6-4ea3-a6fe-81eb3a7b1205","metadata":{},"outputs":[{"ename":"IndexError","evalue":"list index out of range","output_type":"error","traceback":["\u001b[1;31m---------------------------------------------------------------------------\u001b[0m","\u001b[1;31mIndexError\u001b[0m                                Traceback (most recent call last)","Cell \u001b[1;32mIn[3], line 2\u001b[0m\n\u001b[0;32m      1\u001b[0m a \u001b[38;5;241m=\u001b[39m [\u001b[38;5;241m1\u001b[39m, \u001b[38;5;241m2\u001b[39m, \u001b[38;5;241m3\u001b[39m]\n\u001b[1;32m----> 2\u001b[0m \u001b[43ma\u001b[49m\u001b[43m[\u001b[49m\u001b[38;5;241;43m10\u001b[39;49m\u001b[43m]\u001b[49m\n","\u001b[1;31mIndexError\u001b[0m: list index out of range"]}],"source":["a = [1, 2, 3]\n","a[10]"]},{"cell_type":"markdown","id":"544ba735-a45a-4484-9282-0af8a5c353f2","metadata":{},"source":["<code>IndexError</code> -- en este caso, el error se produjo porque se intentó acceder a los datos de una lista utilizando un índice que no existe para esta lista."]},{"cell_type":"markdown","metadata":{},"source":["Hay muchos otros tipos de [errores y excepciones](https://docs.python.org/3/library/exceptions.html) en Python:\n","\n","| **Tipo de Excepción**   | **Descripción**                                                                                       | **Ejemplo**                                                                                       |\n","|--------------------------|-------------------------------------------------------------------------------------------------------|---------------------------------------------------------------------------------------------------|\n","| `ZeroDivisionError`       | Ocurre cuando se intenta dividir un número por cero.                                                  | `x = 10 / 0`  (Genera un `ZeroDivisionError`)                                                     |\n","| `IndexError`              | Se genera cuando se intenta acceder a un índice fuera del rango de una lista o secuencia.            | `lista = [1, 2, 3]; x = lista[5]`  (Genera un `IndexError`)                                      |\n","| `KeyError`                | Se produce cuando se intenta acceder a una clave que no existe en un diccionario.                    | `d = {'a': 1}; x = d['b']`  (Genera un `KeyError`)                                                |\n","| `ValueError`              | Ocurre cuando una función recibe un argumento con un tipo o valor inapropiado.                        | `int('abc')`  (Genera un `ValueError`)                                                           |\n","| `TypeError`               | Se lanza cuando se realiza una operación entre tipos de datos incompatibles.                          | `'2' + 2`  (Genera un `TypeError`)                                                                |\n","| `FileNotFoundError`       | Aparece cuando se intenta abrir un archivo que no existe.                                            | `open('archivo_inexistente.txt')`  (Genera un `FileNotFoundError`)                               |\n","| `AttributeError`          | Se produce cuando se intenta acceder a un atributo que no existe en un objeto.                      | `'cadena'.non_existent_method()`  (Genera un `AttributeError`)                                   |\n","| `NameError`               | Ocurre cuando se hace referencia a una variable que no ha sido definida.                             | `print(variable_no_definida)`  (Genera un `NameError`)                                           |\n","| `SyntaxError`             | Se lanza cuando hay un error en la sintaxis del código.                                               | `if True print(\"Hola\")`  (Genera un `SyntaxError`)                                               |\n","| `ImportError`             | Se produce cuando hay un problema al intentar importar un módulo.                                   | `import modulo_inexistente`  (Genera un `ImportError`)                                           |\n","| `IOError`                 | Se genera cuando ocurre un error relacionado con operaciones de entrada/salida, como leer o escribir en un archivo. | `f = open('/ruta/invalida', 'r')`  (Genera un `IOError`)                                        |\n","| `OverflowError`           | Aparece cuando una operación excede el límite de un tipo de dato, como un número que es demasiado grande para ser representado. | `import sys; x = sys.maxsize * 2`  (Genera un `OverflowError`)                                   |\n","| `RuntimeError`            | Se produce cuando ocurre un error genérico que no se ajusta a otro tipo de excepción más específico.  | `raise RuntimeError('Error inesperado')`  (Genera un `RuntimeError`)                             |\n","| `StopIteration`           | Se lanza para indicar que no hay más elementos en un iterador.                                        | `iterador = iter([1, 2, 3]); next(iterador); next(iterador); next(iterador); next(iterador)`  (Genera un `StopIteration`) |"]},{"cell_type":"markdown","id":"9afc2b7d-c1ad-4972-a366-fa01fa2a9fbd","metadata":{},"source":["## Gestion de excepciones\n"]},{"cell_type":"markdown","id":"76169e7c-d03e-4937-b30f-90cb9adcd19a","metadata":{},"source":["A continuación, aprenderás a manejar excepciones. Entenderás cómo hacer que tu programa realice tareas específicas en lugar de detener la ejecución del código cuando se encuentra una excepción."]},{"cell_type":"markdown","id":"c2bc0845-fc1b-4cf4-9fb3-e3e247a41fe3","metadata":{},"source":["### Try Except\n"]},{"cell_type":"markdown","id":"31023533-37ef-45b3-a771-94f3c57d4aa1","metadata":{},"source":["Un <code>try except</code> te permitirá ejecutar código que podría generar una excepción y, en caso de que ocurra alguna excepción (o una específica), podemos manejarla o capturarla y ejecutar un código determinado. Esto nos permitirá continuar con la ejecución de nuestro programa incluso si se presenta una excepción.\n","\n","Python intenta ejecutar el código en el bloque <code>try</code>. En este caso, si ocurre alguna excepción en el código dentro del bloque <code>try</code>, esta será capturada y el código dentro del bloque <code>except</code> se ejecutará. Después de eso, el código que viene <em>después</em> del try except se ejecutará.\n"]},{"cell_type":"code","execution_count":null,"id":"69887421-969e-41ca-9e53-7b28ee38f202","metadata":{},"outputs":[],"source":["# potential code before try catch\n","\n","try:\n","    # code to try to execute\n","except:\n","    # code to execute if there is an exception\n","    \n","# code that will still execute if there is an exception"]},{"cell_type":"markdown","id":"772cb691-a87e-4289-a1c9-6e1d878af471","metadata":{},"source":["### Try Except - Ejemplo\n"]},{"cell_type":"markdown","id":"69df7a84-2138-4ee5-bdd6-c3b6d649a98c","metadata":{},"source":["En este ejemplo, estamos tratando de dividir un número proporcionado por el usuario, guardar el resultado en la variable <code>a</code>, y luego nos gustaría imprimir el resultado de la operación. Al tomar una entrada del usuario y dividir un número por ella, hay un par de excepciones que pueden ocurrir. Por ejemplo, si dividimos por cero. Intenta ejecutar el siguiente bloque de código con <code>b</code> como un número. Una excepción solo se generará si <code>b</code> es cero.\n"]},{"cell_type":"code","execution_count":15,"id":"5fc4522c-d4aa-46c3-8e08-3313417aad56","metadata":{},"outputs":[{"name":"stdout","output_type":"stream","text":["There was an error\n"]}],"source":["a = 1\n","\n","try:\n","    b = int(input(\"Please enter a number to divide a\"))\n","    a = a/b\n","    print(\"Success a=\",a)\n","except:\n","    print(\"There was an error\")"]},{"cell_type":"markdown","id":"0de42528-2b3b-40d1-8f33-5a90d47ff88c","metadata":{},"source":["### Try Except Específico\n"]},{"cell_type":"markdown","id":"f2e782cc-9fc0-4ba5-955e-ee1d95412996","metadata":{},"source":["Un <code>try except</code> específico te permite capturar excepciones concretas y ejecutar cierto código dependiendo de la excepción. Esto es útil si no deseas lidiar con algunas excepciones y prefieres que la ejecución se detenga. También puede ayudarte a encontrar errores en tu código que quizás no habías notado. Además, te permite diferenciar las respuestas ante diferentes excepciones. En este caso, el código después del <code>try except</code> podría no ejecutarse dependiendo del error que ocurra.\n"]},{"cell_type":"code","execution_count":null,"id":"01a357c8-2143-4305-9191-9059c4a991a2","metadata":{},"outputs":[],"source":["# potential code before try catch\n","\n","try:\n","    # code to try to execute\n","except (ZeroDivisionError, NameError):\n","    # code to execute if there is an exception of the given types\n","    \n","# code that will execute if there is no exception or a one that we are handling"]},{"cell_type":"code","execution_count":null,"id":"54a265b6-c117-4275-ab5f-23bb3879bdd5","metadata":{},"outputs":[],"source":["# potential code before try catch\n","\n","try:\n","    # code to try to execute\n","except ZeroDivisionError:\n","    # code to execute if there is a ZeroDivisionError\n","except NameError:\n","    # code to execute if there is a NameError\n","    \n","# code that will execute if there is no exception or a one that we are handling"]},{"cell_type":"markdown","id":"2c9a0dd4-12d0-47ff-bddf-f0456198b3c6","metadata":{},"source":["También puedes tener un <code>except</code> vacío al final para capturar una excepción inesperada. Esto es útil para capturar cualquier error que no hayas anticipado explícitamente en los bloques de excepciones anteriores. Sin embargo, se recomienda usarlo con precaución, ya que puede hacer más difícil depurar el código y no proporciona detalles específicos sobre el tipo de excepción."]},{"cell_type":"code","execution_count":null,"id":"2e2790b8-0cd4-4274-9e7d-1f3e5adb600b","metadata":{},"outputs":[],"source":["# potential code before try catch\n","\n","try:\n","    # code to try to execute\n","except ZeroDivisionError:\n","    # code to execute if there is a ZeroDivisionError\n","except NameError:\n","    # code to execute if there is a NameError\n","except:\n","    # code to execute if ther is any exception\n","    \n","# code that will execute if there is no exception or a one that we are handling"]},{"cell_type":"markdown","id":"d49604b7-a9e1-4d75-8d80-4437a3d5a71f","metadata":{},"source":["### Try Except Específico - Ejemplo\n"]},{"cell_type":"markdown","id":"71393f3a-d0be-44b3-8684-3a1a83d19258","metadata":{},"source":["Este es el mismo ejemplo que el anterior, pero ahora añadiremos mensajes diferenciados dependiendo de la excepción, haciendo saber al usuario qué es lo que está mal en la entrada.\n"]},{"cell_type":"code","execution_count":14,"id":"4a3ec1a4-d2a8-4eee-8ce4-28d5af044262","metadata":{},"outputs":[{"name":"stdout","output_type":"stream","text":["The number you provided cant divide 1 because it is 0\n"]}],"source":["a = 1\n","\n","try:\n","    b = int(input(\"Please enter a number to divide a\"))\n","    a = a/b\n","    print(\"Success a=\",a)\n","except ZeroDivisionError:\n","    print(\"The number you provided cant divide 1 because it is 0\")\n","except ValueError:\n","    print(\"You did not provide a number\")\n","except:\n","    print(\"Something went wrong\")\n","        \n"]},{"cell_type":"markdown","id":"703798e4-e388-4852-b035-5e6e7770301f","metadata":{},"source":["### Try Except Else & Finally"]},{"cell_type":"markdown","id":"c8167c06-e06e-4dcf-bc42-22a974727daf","metadata":{},"source":["El <code>else</code> permite verificar si no hubo ninguna excepción al ejecutar el bloque <code>try</code>. Esto es útil cuando queremos ejecutar algo solo si no ocurrieron errores en el bloque <code>try</code>."]},{"cell_type":"code","execution_count":null,"id":"d28f5ab2-12d8-41e6-a475-4d80f1b5e0bd","metadata":{},"outputs":[],"source":["# potential code before try catch\n","\n","try:\n","    # code to try to execute\n","except ZeroDivisionError:\n","    # code to execute if there is a ZeroDivisionError\n","except NameError:\n","    # code to execute if there is a NameError\n","except:\n","    # code to execute if ther is any exception\n","else:\n","    # code to execute if there is no exception\n","    \n","# code that will execute if there is no exception or a one that we are handling"]},{"cell_type":"markdown","id":"a7f70677-f83f-4937-8ded-14f130b0946e","metadata":{},"source":["El <code>finally</code> nos permite ejecutar siempre algo, incluso si ocurre una excepción o no. Esto generalmente se usa para significar el final del bloque <code>try except</code>, y es útil para liberar recursos, cerrar archivos, conexiones o realizar cualquier otra acción de limpieza."]},{"cell_type":"code","execution_count":null,"id":"d72f42d3-48c7-457a-8bd3-78a1f8577d7c","metadata":{},"outputs":[],"source":["# potential code before try catch\n","\n","try:\n","    # code to try to execute\n","except ZeroDivisionError:\n","    # code to execute if there is a ZeroDivisionError\n","except NameError:\n","    # code to execute if there is a NameError\n","except:\n","    # code to execute if ther is any exception\n","else:\n","    # code to execute if there is no exception\n","finally:\n","    # code to execute at the end of the try except no matter what\n","    \n","# code that will execute if there is no exception or a one that we are handling"]},{"cell_type":"markdown","id":"7d3ac648-2ec1-4563-afb5-7537e88ec8f5","metadata":{},"source":["### Try Except Else & Finally - Ejemplo\n"]},{"cell_type":"code","execution_count":10,"id":"22ccff74-a80e-4751-8e64-bd3642a571c2","metadata":{},"outputs":[{"name":"stdout","output_type":"stream","text":["success a= 0.2\n"]}],"source":["a = 1\n","\n","try:\n","    b = int(input(\"Please enter a number to divide a\"))\n","    a = a/b\n","except ZeroDivisionError:\n","    print(\"The number you provided cant divide 1 because it is 0\")\n","except ValueError:\n","    print(\"You did not provide a number\")\n","except:\n","    print(\"Something went wrong\")\n","else:\n","    print(\"success a=\",a)"]},{"cell_type":"markdown","id":"32d34382-e3ec-400d-918f-7fd6d993da33","metadata":{},"source":["Ahora, vamos a informar al usuario que hemos terminado de procesar su respuesta. Utilizando el <code>finally</code>, agreguemos una impresión para indicarlo."]},{"cell_type":"code","execution_count":12,"id":"de1828d1-4470-4bed-b3aa-e82eeee56f1f","metadata":{},"outputs":[{"name":"stdout","output_type":"stream","text":["You did not provide a number\n","Processing Complete\n"]}],"source":["a = 1\n","\n","try:\n","    b = int(input(\"Please enter a number to divide a\"))\n","    a = a/b\n","except ZeroDivisionError:\n","    print(\"The number you provided cant divide 1 because it is 0\")\n","except ValueError:\n","    print(\"You did not provide a number\")\n","except:\n","    print(\"Something went wrong\")\n","else:\n","    print(\"success a=\",a)\n","finally:\n","    print(\"Processing Complete\")"]}],"metadata":{"kernelspec":{"display_name":"Python 3","language":"python","name":"python3"},"language_info":{"codemirror_mode":{"name":"ipython","version":3},"file_extension":".py","mimetype":"text/x-python","name":"python","nbconvert_exporter":"python","pygments_lexer":"ipython3","version":"3.12.1"},"prev_pub_hash":"abb9917dfd7a8c219ca8f58ab7002967472e0fef9004ead21334c695bee6a161"},"nbformat":4,"nbformat_minor":4}
